<robot name="cartesian">
  <material name="blue">
    <color rgba="0 0 0.6 1" />
  </material>
  <material name="yellow">
    <color rgba="1 1 0.5 1" />
  </material>
  <material name="green">
    <color rgba="0.5 1 0 1" />
  </material>
  <material name="light_red">
    <color rgba="0.9 0 0 1" />
  </material>
  <material name="white">
    <color rgba="1 1 1 1" />
  </material>
  <material name="grey">
    <color rgba="0.8 0.8 0.8 1" />
  </material>
  <material name="black">
    <color rgba="0 0 0 1" />
  </material>
  <link name="world" />
  <joint name="joint_fix" type="fixed">
    <parent link="world" />
    <child link="world_base" />
  </joint>
  <link name="world_base">
    <collision>
      <origin xyz="0 0 -1" rpy="0 0 0" />
      <geometry>
        <box size="0.2 0.2 0.1" />
      </geometry>
    </collision>
    <visual>
      <origin xyz="0 0 -1" rpy="0 0 0" />
      <geometry>
        <box size="0.2 0.2 0.1" />
      </geometry>
      <material name="black" />
    </visual>
    <inertial>
      <origin xyz="0 0 -1" rpy="0 0 0" />
      <mass value="1" />
      <inertia ixx="0.001" ixy="0" ixz="0" iyy="0.001" iyz="0" izz="0.01" />
    </inertial>
  </link>
  <joint name="base_zaxis_joint" type="fixed">
    <parent link="world_base" />
    <child link="z_axis_link" />
  </joint>
  <link name="z_axis_link">
    <collision>
      <origin xyz="0 0 1.0" rpy="0 0 0" />
      <geometry>
        <box size="0.2 0.2 4" />
      </geometry>
    </collision>
    <visual>
      <origin xyz="0 0 1.0" rpy="0 0 0" />
      <geometry>
        <box size="0.2 0.2 4" />
      </geometry>
      <material name="black" />
    </visual>
    <inertial>
      <origin xyz="0 0 1.0" rpy="0 0 0" />
      <mass value="1" />
      <inertia ixx="0.001" ixy="0" ixz="0" iyy="0.001" iyz="0" izz="0.01" />
    </inertial>
  </link>
  <joint name="z_axis_link_prismatic_joint" type="prismatic">
    <parent link="z_axis_link" />
    <child link="x_axis_link" />
    <origin xyz="0 0 -1.0" rpy="0 0 0" />
    <axis xyz="0 0 1" />
    <limit effort="100" velocity="100" lower="-1.0" upper="3.0" />
  </joint>
  <link name="x_axis_link">
    <collision>
      <origin xyz="2.0 0 1.0" rpy="0 0 0" />
      <geometry>
        <box size="4 0.2 0.2" />
      </geometry>
    </collision>
    <visual>
      <origin xyz="2.0 0 1.0" rpy="0 0 0" />
      <geometry>
        <box size="4 0.2 0.2" />
      </geometry>
      <material name="grey" />
    </visual>
    <inertial>
      <origin xyz="2.0 0 1.0" rpy="0 0 0" />
      <mass value="1" />
      <inertia ixx="0.001" ixy="0" ixz="0" iyy="0.001" iyz="0" izz="0.01" />
    </inertial>
  </link>
  <joint name="x_axis_link_prismatic_joint" type="prismatic">
    <parent link="x_axis_link" />
    <child link="y_axis_link" />
    <origin xyz="[-2.0, 0, 1.0]" rpy="0 0 0" />
    <axis xyz="1 0 0" />
    <limit effort="100" velocity="100" lower="0" upper="4" />
  </joint>
  <link name="y_axis_link">
    <collision>
      <origin xyz="0.0 2.0 0.0" rpy="0 0 0" />
      <geometry>
        <box size="0.2 4 0.2" />
      </geometry>
    </collision>
    <visual>
      <origin xyz="0.0 2.0 0.0" rpy="0 0 0" />
      <geometry>
        <box size="0.2 4 0.2" />
      </geometry>
      <material name="blue" />
    </visual>
    <inertial>
      <origin xyz="0.0 2.0 0.0" rpy="0 0 0" />
      <mass value="1" />
      <inertia ixx="0.001" ixy="0" ixz="0" iyy="0.001" iyz="0" izz="0.01" />
    </inertial>
  </link>
  <joint name="y_axis_link_prismatic_joint" type="prismatic">
    <parent link="y_axis_link" />
    <child link="base_gripper" />
    <origin xyz="[0.0, 2.0, 0.0]" rpy="0 0 0" />
    <axis xyz="0 1 0" />
    <limit effort="100" velocity="100" lower="-2.0" upper="2.0" />
  </joint>
  <link name="base_gripper">
    <collision>
      <origin xyz="0.0 0.0 -0.2" rpy="0 0 0" />
      <geometry>
        <box size="1 1 0.1" />
      </geometry>
    </collision>
    <visual>
      <origin xyz="0.0 0.0 -0.2" rpy="0 0 0" />
      <geometry>
        <box size="1 1 0.1" />
      </geometry>
      <material name="grey" />
    </visual>
    <inertial>
      <origin xyz="0.0 0.0 -0.2" rpy="0 0 0" />
      <mass value="1" />
      <inertia ixx="0.001" ixy="0" ixz="0" iyy="0.001" iyz="0" izz="0.01" />
    </inertial>
  </link>
  <joint name="base_gripper_revolution_joint" type="continuous">
    <parent link="base_gripper" />
    <child link="hand_gripper" />
    <origin xyz="0.0 0.0 -0.2" rpy="0 0 0" />
    <axis xyz="0 0 1" />
    <limit effort="100" velocity="100" lower="-1.5708" upper="1.5708" />
  </joint>
  <link name="hand_gripper">
    <collision>
      <origin xyz="0.0 0.0 -0.30000000000000004" rpy="0 0 0" />
      <geometry>
        <box size="2 1 0.1" />
      </geometry>
    </collision>
    <visual>
      <origin xyz="0.0 0.0 -0.30000000000000004" rpy="0 0 0" />
      <geometry>
        <box size="2 1 0.1" />
      </geometry>
      <material name="blue" />
    </visual>
    <inertial>
      <origin xyz="0.0 0.0 -0.30000000000000004" rpy="0 0 0" />
      <mass value="1" />
      <inertia ixx="0.001" ixy="0" ixz="0" iyy="0.001" iyz="0" izz="0.01" />
    </inertial>
  </link>
  <joint name="hand_gripper_right_finger_joint" type="prismatic">
    <parent link="hand_gripper" />
    <child link="right_finger" />
    <origin xyz="0.0 0.0 -0.2" rpy="0 0 0" />
    <axis xyz="1 0 0" />
    <limit effort="100" velocity="100" lower="-1" upper="0" />
  </joint>
  <link name="right_finger">
    <collision>
      <origin xyz="1.0 0.0 -0.65" rpy="0 0 0" />
      <geometry>
        <box size="0.1 1 1" />
      </geometry>
    </collision>
    <visual>
      <origin xyz="1.0 0.0 -0.65" rpy="0 0 0" />
      <geometry>
        <box size="0.1 1 1" />
      </geometry>
      <material name="white" />
    </visual>
    <inertial>
      <origin xyz="1.0 0.0 -0.65" rpy="0 0 0" />
      <mass value="1" />
      <inertia ixx="0.001" ixy="0" ixz="0" iyy="0.001" iyz="0" izz="0.01" />
    </inertial>
  </link>
  <joint name="hand_gripper_left_finger_joint" type="prismatic">
    <parent link="hand_gripper" />
    <child link="left_finger" />
    <origin xyz="0.0 0.0 -0.2" rpy="0 0 0" />
    <axis xyz="1 0 0" />
    <limit effort="100" velocity="100" lower="0" upper="1" />
  </joint>
  <link name="left_finger">
    <collision>
      <origin xyz="-1.0 0.0 -0.65" rpy="0 0 0" />
      <geometry>
        <box size="0.1 1 1" />
      </geometry>
    </collision>
    <visual>
      <origin xyz="-1.0 0.0 -0.65" rpy="0 0 0" />
      <geometry>
        <box size="0.1 1 1" />
      </geometry>
      <material name="white" />
    </visual>
    <inertial>
      <origin xyz="-1.0 0.0 -0.65" rpy="0 0 0" />
      <mass value="1" />
      <inertia ixx="0.001" ixy="0" ixz="0" iyy="0.001" iyz="0" izz="0.01" />
    </inertial>
  </link>
</robot>