<?xml version="1.0"?>
<robot name="gripper">

    <material name="blue">
        <color rgba="0 0 0.8 1"/>
    </material>

    <material name="white">
        <color rgba="1 1 1 1"/>
    </material>

    <material name="grey">
        <color rgba=".5 .5 .5 1"/>
    </material>

    <link name="base_link">
        <visual>
            <geometry>
                <cylinder length="0.2" radius="0.01"/>
            </geometry>
            <origin rpy="0 1.57075 0 " xyz="0.1 0 0"/>
            <material name="grey"/>
        </visual>
    </link>

  <joint name="left_gripper_joint" type="planar">
    <origin rpy="0 0 0" xyz="0.2 0.01 0"/>
    <parent link="base_link"/>
    <child link="left_gripper"/>
  </joint>

  <link name="left_gripper">
    <visual>
      <origin rpy="0.0 0 0" xyz="0 0 0"/>
      <geometry>
        <box size="0.1 0.02 0.1"/>
      </geometry>
      <material name="blue"/>
    </visual>
  </link>

  <joint name="left_tip_joint" type="fixed">
    <parent link="left_gripper"/>
    <child link="left_tip"/>
  </joint>

  <link name="left_tip">
    <visual>zz
      <origin rpy="0.0 0 0" xyz="0.09137 0.00495 0"/>
      <geometry>
        <mesh filename="package://urdf_tutorial/meshes/l_finger_tip.dae"/>
      </geometry>
    </visual>
  </link>
  <joint name="right_gripper_joint" type="planar">
    <origin rpy="0 0 0" xyz="0.2 -0.01 0"/>
    <parent link="base_link"/>
    <child link="right_gripper"/>
  </joint>

  <link name="right_gripper">
    <visual>
      <origin rpy="-3.1415 0 0" xyz="0 0 0"/>
      <geometry>
          <box size="0.1 0.02 0.1"/>
      </geometry>
      <material name="white"/>
    </visual>
  </link>

  <joint name="right_tip_joint" type="fixed">
    <parent link="right_gripper"/>
    <child link="right_tip"/>
  </joint>

  <link name="right_tip">
    <visual>
      <origin rpy="-3.1415 0 0" xyz="0.09137 0.00495 0"/>
      <geometry>
        <mesh filename="package://urdf_tutorial/meshes/l_finger_tip.dae"/>
      </geometry>
    </visual>
  </link>
</robot>